<?xml version="1.0"?>
<robot xmlns:xacro="http://www.ros.org/wiki/xacro" name="tb_sim">
  <!-- Define robot physical and appearance model-->
  <!-- Using dummy/roundly estimated number for inertia, friction model-->

  <!-- IMPROVE
  * More simplify robot mesh files to run faster
  * Add material and calculate precise inertia tensor
  * Modify the friction model to get nature physical interaction-->

 
 <link name="footprint">
 <visual>
      <origin xyz="0 0 0" rpy="0 0 0" />
      <geometry>
        <box size="0.001 0.001 0.001" />
      </geometry>
       <material name="Blue">
	<color rgba="0.0 0.0 0.8 1.0"/>
  </material>
    </visual>

    <collision>
      <origin xyz="0 0 0.017" rpy="0 0 0" />
      <geometry>
        <box size="0.001 0.001 0.001" />
      </geometry>
    </collision>
    </link>
  <joint name="footprint_joint" type="fixed">
    <origin rpy="0 0.0 0" xyz="0.0 0.0 -0.076"/>
    <parent link="base_link"/>
    <child link="footprint"/>
    <axis xyz="0 0 0"/>
  </joint>

  <link name="base_link">
    <inertial>
      <origin rpy="0.0 0.0 0.0" xyz="-0.15 0.0 0.01"/>
      <mass value="5.5"/>
      <inertia ixx="0.03158" ixy="0" ixz="0" iyy="0.04418" iyz="0" izz="0.069898"/>
    </inertial>
    <visual>
      <origin rpy="0 0 0" xyz="0 0 0"/>
      <geometry>
        <mesh filename="package://tb_description/meshes/base_link.STL"/>
      </geometry>
    </visual>
    <collision>
      <origin rpy="0 0 0" xyz="0 0 0"/>
      <geometry>
        <mesh filename="package://tb_description/meshes/base_link.STL"/>
      </geometry>
    </collision>
  </link>
  
  <link name="wheel_left_link">
    <inertial>
      <mass value="0.2"/>
      <inertia ixx="0.00039792" ixy="0" ixz="0" iyy="0.00078467" iyz="0" izz="0.00039792"/>
    </inertial>
    <visual>
      <geometry>
        <mesh filename="package://tb_description/meshes/wheel_link.STL"/>
      </geometry>
     <material name="Blue">
	<color rgba="0.0 0.0 0.8 1.0"/>
  </material>
    </visual>
    <collision>
      <geometry>
        <mesh filename="package://tb_description/meshes/wheel_link.STL"/>
      </geometry>
    </collision>
  </link>
  <joint name="wheel_left_joint" type="continuous">
    <origin rpy="0 0 0" xyz="0 0.165 0"/>
    <parent link="base_link"/>
    <child link="wheel_left_link"/>
    <axis xyz="0 1 0"/>
  </joint>
 <link name="wheel_right_link">
    <inertial>
      <mass value="0.2"/>
      <inertia ixx="0.00039792" ixy="0" ixz="0" iyy="0.00078467" iyz="0" izz="0.00039792"/>
    </inertial>
    <visual>
      <geometry>
        <mesh filename="package://tb_description/meshes/wheel_link.STL"/>
      </geometry>
      <material name="Blue">
	<color rgba="0.0 0.0 0.8 1.0"/>
  </material>
    </visual>
    <collision>
      <geometry>
        <mesh filename="package://tb_description/meshes/wheel_link.STL"/>
      </geometry>
    </collision>
  </link>
  <joint name="wheel_right_joint" type="continuous">
    <origin rpy="0 0 0" xyz="0 -0.165 0"/>
    <parent link="base_link"/>
    <child link="wheel_right_link"/>
    <axis xyz="0 1 0"/>
  </joint>
  
    <link name="caster_link">
    <inertial>
      <origin rpy="0 0 0" xyz="-0.016859 0 -0.039"/>
      <mass value="0.12725"/>
      <inertia ixx="0.00013389" ixy="-3.291E-08" ixz="-5.4328E-05" iyy="0.00016302" iyz="-4.433E-08" izz="9.9804E-05"/>
    </inertial>
    <visual>
      <origin rpy="0 0 0" xyz="0 0 0"/>
      <geometry>
        <mesh filename="package://tb_description/meshes/caster_link.STL"/>
      </geometry>
    </visual>
    <collision>
      <origin rpy="0 0 0" xyz="0 0 0"/>
      <geometry>
        <mesh filename="package://tb_description/meshes/caster_link.STL"/>
      </geometry>
    </collision>
  </link>
  <joint name="caster_joint" type="continuous">
    <origin rpy="0 0 0" xyz="-0.32849 0 0.036"/>
    <parent link="base_link"/>
    <child link="caster_link"/>
    <axis xyz="0 0 1"/>
    <safety_controller k_velocity="0"/>
  </joint>
   <link name="caster_wheel_link">
    <inertial>
      <origin rpy="0 0 0" xyz="0 7.5E-05 0"/>
      <mass value="0.055271"/>
      <inertia ixx="2.6207E-05" ixy="0" ixz="0" iyy="4.8328E-05" iyz="0" izz="2.6207E-05"/>
    </inertial>
    <visual>
      <origin rpy="0 0 0" xyz="0 0 0"/>
      <geometry>
        <mesh filename="package://tb_description/meshes/caster_wheel_link.STL"/>
      </geometry>
    </visual>
    <collision>
      <origin rpy="0 0 0" xyz="0 0 0"/>
      <geometry>
        <mesh filename="package://tb_description/meshes/caster_wheel_link.STL"/>
      </geometry>
    </collision>
  </link>
  <joint name="caster_wheel_joint" type="continuous">
    <origin rpy="0 0 0" xyz="-0.039059 0 -0.075"/>
    <parent link="caster_link"/>
    <child link="caster_wheel_link"/>
    <axis xyz="0 1 0"/>
    <safety_controller k_velocity="0"/>
  </joint>
  
   <link name="tube_link">
    <inertial>
      <origin rpy="0 0 0" xyz="0.02 0 0.6"/>
      <mass value="2"/>
      <inertia ixx="0.2083333333" ixy="0.0" ixz="0.0" iyy="0.2083333333" iyz="0.0" izz="0.000905"/>
    </inertial>
    <visual>
      <origin rpy="0 0 0" xyz="0 0 0"/>
      <geometry>
        <mesh filename="package://tb_description/meshes/tube_link.STL"/>
      </geometry>
    </visual>
    <collision>
      <origin rpy="0 0 0" xyz="0 0 0"/>
      <geometry>
        <mesh filename="package://tb_description/meshes/tube_link.STL"/>
      </geometry>
    </collision>

  
  </link>
  <joint name="tube_joint" type="fixed">
    <origin rpy="0 -0.18326 0" xyz="-0.026814 0 0.083753"/>
    <parent link="base_link"/>
    <child link="tube_link"/>
    <axis xyz="0 0 0"/>
    <safety_controller k_velocity="0"/>
  </joint>
  
  <link name="display_link">
    <inertial>
      <origin rpy="0 0 0" xyz="0.02866 0.0042627 0.019125"/>
      <mass value="0.3"/>
      <inertia ixx="0.0015625" ixy="0" ixz="0" iyy="0.000625" iyz="0" izz="0.0010625"/>
    </inertial>
    <visual>
      <origin rpy="0 0 0" xyz="0 0 0"/>
      <geometry>
        <mesh filename="package://tb_description/meshes/display_link.STL"/>
      </geometry>
    </visual>
    <collision>
      <origin rpy="0 0 0" xyz="0 0 0"/>
      <geometry>
        <mesh filename="package://tb_description/meshes/display_link.STL"/>
      </geometry>
    </collision>
  </link>
  <joint name="neck_joint" type="continuous">
    <origin rpy="0 0 0" xyz="0.14191 0 1.1557"/>
    <parent link="tube_link"/>
    <child link="display_link"/>
    <axis xyz="0.0 1 0.0"/>
    <safety_controller k_velocity="0"/>
  </joint>
  
  <link name="laser_frame">
    <inertial>
      <origin
        xyz="-0.00029774 0.0066667 0.00013047"
        rpy="0 0 0" />
      <mass
        value="0.15717" />
      <inertia
        ixx="6.7885E-05"
        ixy="-1.3987E-07"
        ixz="-8.1554E-07"
        iyy="0.00013173"
        iyz="-9.0932E-08"
        izz="7.1972E-05"/>
    </inertial>
    <visual>
      <geometry>
      <cylinder radius="0.05" length="0.04"/>
        <!--mesh
          filename="package://tb_description/meshes/ydlidar.dae" /-->
      </geometry>
      <material
        name="">
        <color
          rgba="0.64706 0.61961 0.58824 1" />
      </material>
    </visual>
    <collision>
      <origin
        xyz="0 0 0"
        rpy="0 0 0" />
      <geometry>
      <cylinder radius="0.05" length="0.04"/>
        <!--mesh
          filename="package://ydlidar/meshes/ydlidar.dae" /-->
      </geometry>
    </collision>
  </link>
  <joint name="laser_range_mount_joint" type="fixed">
    <origin rpy="0.0 0.0 0" xyz="-0.05 0 0.65"/>
    <parent link="base_link"/>
    <child link="laser_frame"/>
  </joint>
  
  <link name="main_cam">
    <visual>
      <geometry>
        <box size="0.01 0.01 0.01"/>
      </geometry>
    </visual>
    <collision>
      <geometry>
        <box size="0.01 0.01 0.01"/>
      </geometry>
    </collision>
   <inertial>
      <origin
        xyz="-0.00036659 0.00064155 -0.00027052"
        rpy="0 0 0" />
      <mass
        value="0.25482" />
      <inertia
        ixx="8.9194E-05"
        ixy="1.8116E-07"
        ixz="3.6435E-08"
        iyy="0.00018279"
        iyz="2.423E-07"
        izz="0.00011103" />
    </inertial>
  </link>
  <joint name="camera_mount_joint" type="fixed">
    <origin rpy="0.0 -0.183 0.0" xyz="-0.069 0 1.363"/>
    <parent link="base_link"/>
    <child link="main_cam"/>
  </joint> 
  
  

</robot>
